Namespace(dataset='UNB345_3', feat='iat_size', gs='True', header='True', model='OCSVM(rbf)', time='2021-04-01 01:45:14')
***UNB345_3, OCSVM(rbf), iat_size, speedup/data/models/src_dst/iat_size-header_True/UNB345_3/before_proj_False-gs_True/OCSVM(rbf)-std_False_center_False-d_5-None
***0_th repeat
Traceback (most recent call last):
  File "speedup/main_reload_idv.py", line 343, in main
    model_params = load_data(model_params_file)
  File "/Users/kunyang/PycharmProjects/kjl_reload/kjl/utils/tool.py", line 58, in load_data
    with open(in_file, 'rb') as f:
FileNotFoundError: [Errno 2] No such file or directory: 'speedup/data/models/src_dst/iat_size-header_True/UNB345_3/before_proj_False-gs_True/OCSVM(rbf)-std_False_center_False-d_5-None/repeat_0.model.model_params'
Error: UNB345_3, OCSVM(rbf)
***1_th repeat
Traceback (most recent call last):
  File "speedup/main_reload_idv.py", line 343, in main
    model_params = load_data(model_params_file)
  File "/Users/kunyang/PycharmProjects/kjl_reload/kjl/utils/tool.py", line 58, in load_data
    with open(in_file, 'rb') as f:
FileNotFoundError: [Errno 2] No such file or directory: 'speedup/data/models/src_dst/iat_size-header_True/UNB345_3/before_proj_False-gs_True/OCSVM(rbf)-std_False_center_False-d_5-None/repeat_1.model.model_params'
Error: UNB345_3, OCSVM(rbf)
***2_th repeat
Traceback (most recent call last):
  File "speedup/main_reload_idv.py", line 343, in main
    model_params = load_data(model_params_file)
  File "/Users/kunyang/PycharmProjects/kjl_reload/kjl/utils/tool.py", line 58, in load_data
    with open(in_file, 'rb') as f:
FileNotFoundError: [Errno 2] No such file or directory: 'speedup/data/models/src_dst/iat_size-header_True/UNB345_3/before_proj_False-gs_True/OCSVM(rbf)-std_False_center_False-d_5-None/repeat_2.model.model_params'
Error: UNB345_3, OCSVM(rbf)
***3_th repeat
Traceback (most recent call last):
  File "speedup/main_reload_idv.py", line 343, in main
    model_params = load_data(model_params_file)
  File "/Users/kunyang/PycharmProjects/kjl_reload/kjl/utils/tool.py", line 58, in load_data
    with open(in_file, 'rb') as f:
FileNotFoundError: [Errno 2] No such file or directory: 'speedup/data/models/src_dst/iat_size-header_True/UNB345_3/before_proj_False-gs_True/OCSVM(rbf)-std_False_center_False-d_5-None/repeat_3.model.model_params'
Error: UNB345_3, OCSVM(rbf)
***4_th repeat
Traceback (most recent call last):
  File "speedup/main_reload_idv.py", line 343, in main
    model_params = load_data(model_params_file)
  File "/Users/kunyang/PycharmProjects/kjl_reload/kjl/utils/tool.py", line 58, in load_data
    with open(in_file, 'rb') as f:
FileNotFoundError: [Errno 2] No such file or directory: 'speedup/data/models/src_dst/iat_size-header_True/UNB345_3/before_proj_False-gs_True/OCSVM(rbf)-std_False_center_False-d_5-None/repeat_4.model.model_params'
Error: UNB345_3, OCSVM(rbf)
/Library/Frameworks/Python.framework/Versions/3.7/lib/python3.7/site-packages/numpy/core/fromnumeric.py:3373: RuntimeWarning: Mean of empty slice.
  out=out, **kwargs)
/Library/Frameworks/Python.framework/Versions/3.7/lib/python3.7/site-packages/numpy/core/_methods.py:170: RuntimeWarning: invalid value encountered in double_scalars
  ret = ret.dtype.type(ret / rcount)
/Library/Frameworks/Python.framework/Versions/3.7/lib/python3.7/site-packages/numpy/core/_methods.py:234: RuntimeWarning: Degrees of freedom <= 0 for slice
  keepdims=keepdims)
/Library/Frameworks/Python.framework/Versions/3.7/lib/python3.7/site-packages/numpy/core/_methods.py:195: RuntimeWarning: invalid value encountered in true_divide
  arrmean, rcount, out=arrmean, casting='unsafe', subok=False)
/Library/Frameworks/Python.framework/Versions/3.7/lib/python3.7/site-packages/numpy/core/_methods.py:226: RuntimeWarning: invalid value encountered in double_scalars
  ret = ret.dtype.type(ret / rcount)
speedup/out/models_res/src_dst/iat_size-header_True/UNB345_3/before_proj_False-gs_True/OCSVM(rbf)-std_False_center_False-d_5-None/UNB345_3-OCSVM(rbf).dat
