Namespace(dataset='MAWI1_2020', feat='stats', gs='False', header='False', model='Nystrom-GMM(full)', time='2021-04-05 17:55:54')
***MAWI1_2020, Nystrom-GMM(full), stats, speedup/data/models/src_dst/stats-header_False/MAWI1_2020/before_proj_False-gs_False/Nystrom-GMM(full)-std_False_center_False-d_5-full
***0_th repeat
Traceback (most recent call last):
  File "speedup/main_reload_idv.py", line 353, in main
    model_params = load_data(model_params_file)
  File "/home/nano/ky2440/kjl_reload/kjl/utils/tool.py", line 58, in load_data
    with open(in_file, 'rb') as f:
FileNotFoundError: [Errno 2] No such file or directory: 'speedup/data/models/src_dst/stats-header_False/MAWI1_2020/before_proj_False-gs_False/Nystrom-GMM(full)-std_False_center_False-d_5-full/repeat_0.model.model_params'
Error: MAWI1_2020, Nystrom-GMM(full)
***1_th repeat
Traceback (most recent call last):
  File "speedup/main_reload_idv.py", line 353, in main
    model_params = load_data(model_params_file)
  File "/home/nano/ky2440/kjl_reload/kjl/utils/tool.py", line 58, in load_data
    with open(in_file, 'rb') as f:
FileNotFoundError: [Errno 2] No such file or directory: 'speedup/data/models/src_dst/stats-header_False/MAWI1_2020/before_proj_False-gs_False/Nystrom-GMM(full)-std_False_center_False-d_5-full/repeat_1.model.model_params'
Error: MAWI1_2020, Nystrom-GMM(full)
***2_th repeat
Traceback (most recent call last):
  File "speedup/main_reload_idv.py", line 353, in main
    model_params = load_data(model_params_file)
  File "/home/nano/ky2440/kjl_reload/kjl/utils/tool.py", line 58, in load_data
    with open(in_file, 'rb') as f:
FileNotFoundError: [Errno 2] No such file or directory: 'speedup/data/models/src_dst/stats-header_False/MAWI1_2020/before_proj_False-gs_False/Nystrom-GMM(full)-std_False_center_False-d_5-full/repeat_2.model.model_params'
Error: MAWI1_2020, Nystrom-GMM(full)
***3_th repeat
Traceback (most recent call last):
  File "speedup/main_reload_idv.py", line 353, in main
    model_params = load_data(model_params_file)
  File "/home/nano/ky2440/kjl_reload/kjl/utils/tool.py", line 58, in load_data
    with open(in_file, 'rb') as f:
FileNotFoundError: [Errno 2] No such file or directory: 'speedup/data/models/src_dst/stats-header_False/MAWI1_2020/before_proj_False-gs_False/Nystrom-GMM(full)-std_False_center_False-d_5-full/repeat_3.model.model_params'
Error: MAWI1_2020, Nystrom-GMM(full)
***4_th repeat
Traceback (most recent call last):
  File "speedup/main_reload_idv.py", line 353, in main
    model_params = load_data(model_params_file)
  File "/home/nano/ky2440/kjl_reload/kjl/utils/tool.py", line 58, in load_data
    with open(in_file, 'rb') as f:
FileNotFoundError: [Errno 2] No such file or directory: 'speedup/data/models/src_dst/stats-header_False/MAWI1_2020/before_proj_False-gs_False/Nystrom-GMM(full)-std_False_center_False-d_5-full/repeat_4.model.model_params'
Error: MAWI1_2020, Nystrom-GMM(full)
/home/nano/.local/lib/python3.7/site-packages/numpy/core/fromnumeric.py:3335: RuntimeWarning: Mean of empty slice.
  out=out, **kwargs)
/home/nano/.local/lib/python3.7/site-packages/numpy/core/_methods.py:161: RuntimeWarning: invalid value encountered in double_scalars
  ret = ret.dtype.type(ret / rcount)
/home/nano/.local/lib/python3.7/site-packages/numpy/core/_methods.py:217: RuntimeWarning: Degrees of freedom <= 0 for slice
  keepdims=keepdims)
/home/nano/.local/lib/python3.7/site-packages/numpy/core/_methods.py:186: RuntimeWarning: invalid value encountered in true_divide
  arrmean, rcount, out=arrmean, casting='unsafe', subok=False)
/home/nano/.local/lib/python3.7/site-packages/numpy/core/_methods.py:209: RuntimeWarning: invalid value encountered in double_scalars
  ret = ret.dtype.type(ret / rcount)
speedup/out/models_res/src_dst/stats-header_False/MAWI1_2020/before_proj_False-gs_False/Nystrom-GMM(full)-std_False_center_False-d_5-full/MAWI1_2020-Nystrom-GMM(full).dat
